Workbook

Sheet Backlog Backend
A1: ID | B1: Épica | C1: HU | D1: Tarea Backend | E1: Prioridad | F1: Módulo | G1: Responsable | H1: Estado | I1: Notas
A2: T-B00-1 | B2: Entorno y Documentación | C2: — | D2: Inicializar proyecto NestJS con estructura por módulos | E2: Alta | F2: Infraestructura | H2: Done | I2: Base del Hito 1
A3: T-B00-2 | B3: Entorno y Documentación | C3: — | D3: Configurar ValidationPipe global y CORS | E3: Alta | F3: Infraestructura | H3: Done
A4: T-B00-3 | B4: Entorno y Documentación | C4: — | D4: Habilitar documentación OpenAPI/Swagger | E4: Alta | F4: Infraestructura | H4: Done | I4: Disponible en /docs
A5: T-B00-4 | B5: Entorno y Documentación | C5: — | D5: Definir estrategia de ramas (CONTRIBUTING.md) | E5: Media | F5: Infraestructura | H5: Done
A6: T-B00-5 | B6: Entorno y Documentación | C6: — | D6: Escribir README con instrucciones de instalación | E6: Media | F6: Infraestructura | H6: Done
A7: T-B00-6 | B7: Entorno y Documentación | C7: — | D7: Publicar repositorio y crear tag hito-1 | E7: Alta | F7: Infraestructura | H7: Backlog | I7: Requiere acción manual en GitHub
A8: T-B01-1 | B8: Catálogo de Libros | C8: HU-001 | D8: Modelar entidad Libro y DTOs de entrada/salida | E8: Alta | F8: libros | H8: Done
A9: T-B01-2 | B9: Catálogo de Libros | C9: HU-001 | D9: Endpoint POST /libros | E9: Alta | F9: libros | H9: Done
A10: T-B01-3 | B10: Catálogo de Libros | C10: HU-001 | D10: Endpoints GET /libros y GET /libros/:id | E10: Alta | F10: libros | H10: Done
A11: T-B01-4 | B11: Catálogo de Libros | C11: HU-001 | D11: Endpoints PATCH y DELETE /libros/:id | E11: Media | F11: libros | H11: Done
A12: T-B01-5 | B12: Catálogo de Libros | C12: HU-001 | D12: Integrar Open Library para importar por ISBN | E12: Alta | F12: libros | H12: Done | I12: Desafío específico del proyecto
A13: T-B01-6 | B13: Catálogo de Libros | C13: HU-001 | D13: Modelar campo estado (disponible / preventa) | E13: Media | F13: libros | H13: Done | I13: Origen: Site Map
A14: T-B02-1 | B14: Catálogo de Libros | C14: HU-002 | D14: Endpoint de filtro por género y autor | E14: Alta | F14: libros | H14: Done
A15: T-B02-2 | B15: Catálogo de Libros | C15: HU-002 | D15: DTO de parámetros de búsqueda | E15: Media | F15: libros | H15: Done
A16: T-B02-3 | B16: Catálogo de Libros | C16: HU-002 | D16: Definir paginación y orden con UX/UI | E16: Media | F16: libros | H16: In review | I16: Hito 2: page, limit y orden implementados. Falta validar con UX/UI
A17: T-B03-1 | B17: Catálogo de Libros | C17: HU-003 | D17: Confirmar taxonomía de géneros con UX/UI | E17: Media | F17: libros | H17: Backlog
A18: T-B03-2 | B18: Catálogo de Libros | C18: HU-003 | D18: Endpoint de listado de categorías disponibles | E18: Baja | F18: libros | H18: In review | I18: Hito 2: GET /libros/generos
A19: T-B04-1 | B19: Catálogo de Libros | C19: HU-004 | D19: Extender filtros (precio, formato, disponibilidad) | E19: Media | F19: libros | H19: In review | I19: Hito 2: precioMin, precioMax, formato, estado, enStock
A20: T-B05-1 | B20: Motor de Recomendaciones ★ | C20: HU-005 | D20: Diseñar lógica de scoring (género + historial) | E20: Alta | F20: recomendaciones | H20: Done | I20: Esfuerzo diferencial
A21: T-B05-2 | B21: Motor de Recomendaciones ★ | C21: HU-005 | D21: Endpoint GET /recomendaciones/usuario/:id | E21: Alta | F21: recomendaciones | H21: Done | I21: Esfuerzo diferencial
A22: T-B05-3 | B22: Motor de Recomendaciones ★ | C22: HU-005 | D22: Endpoint simulado de registro de compras | E22: Media | F22: recomendaciones | H22: Done
A23: T-B05-4 | B23: Motor de Recomendaciones ★ | C23: HU-005 | D23: Conectar motor al sistema real de Pedidos | E23: Alta | F23: recomendaciones | H23: In review | I23: Hito 2: usa pedidos PAGADOS. Se elimina el endpoint de compras simuladas
A24: T-B06-1 | B24: Perfiles de Librero | C24: HU-006 | D24: Modelar PerfilLibrero y SeccionCurada | E24: Alta | F24: libreros | H24: Done
A25: T-B06-2 | B25: Perfiles de Librero | C25: HU-006 | D25: CRUD de perfil editorial del librero | E25: Alta | F25: libreros | H25: Done
A26: T-B06-3 | B26: Perfiles de Librero | C26: HU-006 | D26: Endpoint de sección curada (agregar/listar) | E26: Alta | F26: libreros | H26: Done
A27: T-B06-4 | B27: Perfiles de Librero | C27: HU-006 | D27: Endpoint "seguir librero" | E27: Media | F27: libreros | H27: Done
A28: T-B07-1 | B28: Gestión de Usuarios | C28: HU-007 | D28: Modelar entidad Usuario y roles | E28: Alta | F28: usuarios | H28: Done
A29: T-B07-2 | B29: Gestión de Usuarios | C29: HU-007 | D29: Endpoint de registro (POST /usuarios) | E29: Alta | F29: usuarios | H29: Done
A30: T-B07-3 | B30: Gestión de Usuarios | C30: HU-007 | D30: Endpoint de login (token simulado) | E30: Alta | F30: usuarios | H30: Done | I30: JWT real pendiente
A31: T-B07-4 | B31: Gestión de Usuarios | C31: HU-007 | D31: Implementar JWT real y guards por rol | E31: Alta | F31: usuarios | H31: In review | I31: Hito 2: JWT real, guard global, @Public y @Roles
A32: T-B07-5 | B32: Gestión de Usuarios | C32: HU-007 | D32: Campo avatarUrl y selección de intereses | E32: Media | F32: usuarios | H32: Done | I32: Origen: Site Map
A33: T-B08-1 | B33: Club de Lectura ★ | C33: HU-008 | D33: Modelar Club, Hilo, Comentario y Progreso | E33: Alta | F33: club-lectura | H33: Done | I33: Esfuerzo diferencial
A34: T-B08-2 | B34: Club de Lectura ★ | C34: HU-008 | D34: CRUD de clubes de lectura | E34: Alta | F34: club-lectura | H34: Done | I34: Esfuerzo diferencial
A35: T-B08-3 | B35: Club de Lectura ★ | C35: HU-008 | D35: Endpoints de hilos de discusión y comentarios | E35: Alta | F35: club-lectura | H35: Done | I35: Esfuerzo diferencial
A36: T-B08-4 | B36: Club de Lectura ★ | C36: HU-008 | D36: Endpoint de progreso de lectura compartido | E36: Media | F36: club-lectura | H36: Done | I36: Esfuerzo diferencial
A37: T-B09-1 | B37: Reseñas | C37: HU-009 | D37: Modelar entidad Reseña | E37: Alta | F37: resenas | H37: Done
A38: T-B09-2 | B38: Reseñas | C38: HU-009 | D38: CRUD de reseñas por libro | E38: Alta | F38: resenas | H38: Done
A39: T-B09-3 | B39: Reseñas | C39: HU-009 | D39: Endpoint "mis reseñas" por usuario | E39: Media | F39: resenas | H39: Done | I39: Origen: Site Map
A40: T-B09-4 | B40: Reseñas | C40: HU-009 | D40: Validar reseña contra historial de compras real | E40: Media | F40: resenas | H40: Backlog | I40: Depende de HU-011
...

Sheet Resumen
B2: Resumen del Backlog — Backend LeeConNos
B4: Distribución por Estado
B5: Estado | C5: Cantidad de tareas
B6: No Status | C6: =COUNTIF('Backlog Backend'!H:H,B6)
B7: Backlog | C7: =COUNTIF('Backlog Backend'!H:H,B7)
B8: Ready | C8: =COUNTIF('Backlog Backend'!H:H,B8)
B9: In progress | C9: =COUNTIF('Backlog Backend'!H:H,B9)
B10: In review | C10: =COUNTIF('Backlog Backend'!H:H,B10)
B11: Done | C11: =COUNTIF('Backlog Backend'!H:H,B11)
B12: Total | C12: =SUM(C6:C11)
B15: Distribución por Épica
B16: Épica | C16: Cantidad de tareas
B17: Entorno y Documentación | C17: =COUNTIF('Backlog Backend'!B:B,B17)
B18: Catálogo de Libros | C18: =COUNTIF('Backlog Backend'!B:B,B18)
B19: Motor de Recomendaciones ★ | C19: =COUNTIF('Backlog Backend'!B:B,B19)
B20: Perfiles de Librero | C20: =COUNTIF('Backlog Backend'!B:B,B20)
B21: Gestión de Usuarios | C21: =COUNTIF('Backlog Backend'!B:B,B21)
B22: Club de Lectura ★ | C22: =COUNTIF('Backlog Backend'!B:B,B22)
B23: Reseñas | C23: =COUNTIF('Backlog Backend'!B:B,B23)
B24: Listas de Deseos | C24: =COUNTIF('Backlog Backend'!B:B,B24)
B25: Pedidos y Compras | C25: =COUNTIF('Backlog Backend'!B:B,B25)
B26: Pagos | C26: =COUNTIF('Backlog Backend'!B:B,B26)
B27: Ofertas y Precios | C27: =COUNTIF('Backlog Backend'!B:B,B27)
B28: Newsletter | C28: =COUNTIF('Backlog Backend'!B:B,B28)
... B37: Integración Web y Mobile | C37: =COUNTIF('Backlog Backend'!B:B,B37)

Sheet Leyenda
B2: Cómo usar este backlog
B4: • | C4: Esta planilla lista las tareas Backend identificadas en los Hitos 1 y 2 de LeeConNos.
B6: • | C6: Completa la columna "Responsable" (resaltada en amarillo) con el nombre de quien ejecuta cada tarea.
B8: • | C8: Actualiza "Estado" a medida que el trabajo avance, usando los mismos valores del tablero Kanban del equipo.
B10: • | C10: Las filas en "Done" corresponden a servicios ya construidos y probados en el proyecto backend.
B12: • | C12: Las filas en "Backlog" son sistemas identificados pero no implementados aún, o planificados para el siguiente hito.
B15: Prioridad
B16: Alta | C16: Bloquea otras tareas o es parte del esfuerzo diferencial del proyecto
B17: Media | C17: Necesaria para completar la funcionalidad, no bloqueante
B18: Baja | C18: Mejora o extensión, puede esperar a hitos posteriores
B20: Estado
B21: No Status | C21: Sin triage todavía
B22: Backlog | C22: Identificada, trabajo aún no iniciado
B23: Ready | C23: Lista para comenzar
B24: In progress | C24: Trabajo en curso
B25: In review | C25: En revisión (Pull Request abierto)
B26: Done | C26: Construida, probada y documentada
